Workbook
Name ABSENCE: #REF!
Name ABSENCE: #REF!
Name ABSENCE: #REF!
Name ABSENCE: #REF!
Name ABSENCE: #REF!
Name ABSENCE: #REF!
Name ABSENCE: #REF!
Name ABSENCE: #REF!
Name ABSENCE: #REF!
Name ABSENCE: #REF!
Name ABSENCE: #REF!
Name ABSENCE: #REF!
Name ABSENCE: #REF!
Name ABSENCE: #REF!
Name ABSENCE: #REF!
Name ABSENCE: #REF!
Name ABSENCE: #REF!
Name ABSENCE: #REF!
Name ABSENCE: #REF!
Name ABSENCE: #REF!
Name ABSENCE: #REF!
Name ABSENCE: #REF!
Name ABSENCE: #REF!
Name ABSENCE: #REF!
Name ABSENCE: #REF!
Name ABSENCE: #REF!
Name ABSENCE: #REF!
Name ABSENCE: #REF!
Name ABSENCE: #REF!
Name ABSENCE: #REF!
Name ABSENCE: #REF!
Name ABSENCE: #REF!
Name ABSENCE: #REF!
Name ABSENCE: #REF!
Name ABSENCES: #REF!
Name ABSENCES: #REF!
Name ABSENCES: #REF!
Name ABSENCES: #REF!
Name ABSENCES: #REF!
Name ABSENCES: #REF!
Name ABSENCES: #REF!
Name ABSENCES: #REF!
Name ABSENCES: #REF!
Name ABSENCES: #REF!
Name ABSENCES: #REF!
Name ABSENCES: #REF!
Name ABSENCES: #REF!
Name ABSENCES: #REF!
Name ABSENCES: #REF!
Name ABSENCES: #REF!
Name ABSENCES: #REF!
Name ABSENCES: #REF!
Name ABSENCES: #REF!
Name ABSENCES: #REF!
Name ABSENCES: #REF!
Name ABSENCES: #REF!
Name ABSENCES: #REF!
Name ABSENCES: #REF!
Name ABSENCES: #REF!
Name ABSENCES: #REF!

Sheet rému
P1: Valeur du point 2013 (signature accord) | R1: 14.51
A2: REMUNERATION DE L'ASTREINTE 2024 ( Accord collectif du 24/04/2013) dès PAIE de Juin 2023 | P2: Valeur du point actuelle | R2: 18.3
P3: Evolution | R3: =(R2-R1)/R1 -> 0.26119917
D4: Niveau 1 | H4: Niveau 2
A5: Catégories | B5: Périodes d'Astreinte | D5: Montant | E5: Si JF tombant sur période | F5: Si entrant dans le cas de la majoration été | G5: Si entrant dans le cas de la majo été et JF tombant pendant période | H5: Montant | I5: Si JF tombant sur période | J5: Si entrant dans le cas de la majoration été | K5: Si entrant dans le cas de la majo été et JF tombant pendant période
A6: A | B6: Week-End | D6: =80*(1+$R$3) -> 100.89593 | E6: =D6+25 -> 125.89593 | F6: =D6*1.3 -> 131.16471 | G6: =F6+25 -> 156.16471 | H6: =50*(1+$R$3) -> 63.059959 | I6: =H6+25 -> 88.059959 | J6: =H6*1.3 -> 81.977946 | K6: =J6+25 -> 106.97795
A7: B | B7: 5 jours continus en semaine | D7: =D6 -> 100.89593 | E7: =D7+25 -> 125.89593 | F7: =D7*1.3 -> 131.16471 | G7: =F7+25 -> 156.16471 | H7: =H6 -> 63.059959 | I7: =H7+25 -> 88.059959 | J7: =H7*1.3 -> 81.977946 | K7: =J7+25 -> 106.97795
A8: C | B8: 6 jours continus en semaine | D8: =110*(1+$R$3) -> 138.73191 | E8: =D8+25 -> 163.73191 | F8: =D8*1.3 -> 180.35148 | G8: =F8+25 -> 205.35148 | H8: =65*(1+$R$3) -> 81.977946 | I8: =H8+25 -> 106.97795 | J8: =H8*1.3 -> 106.57133 | K8: =J8+25 -> 131.57133
A9: D | B9: 7 jours continus en semaine | D9: =140*(1+$R$3) -> 176.56788 | E9: =D9+25 -> 201.56788 | F9: =D9*1.3 -> 229.53825 | G9: =F9+25 -> 254.53825 | H9: =90*(1+$R$3) -> 113.50793 | I9: =H9+25 -> 138.50793 | J9: =H9*1.3 -> 147.5603 | K9: =J9+25 -> 172.5603
B11: Astreinte mixte | D11: = verser l'indemnité de niveau 1 et paiement des temps de trajet et d'intervention (idem niveau 2)
A13: Majoration jour férié : Chaque jour férié compris dans une période d'astreinte donnera lieu à une majoration de 25€
A15: Majoration pour période d'été (1er juin au 30 septembre) : Lorsque qu'en cas de réduction d'effectif les périodes d'astreinte sont renouvelées au rythme de 7 jours maximum toutes les 2 semaines , le montant de l'indemnité dans ce cas sera majoré de 30%.

Sheet Niveau 1 Janv
D2: ASTREINTE niveau 1 | L2: 45292
B5: RETOUR DU PRESENT DOCUMENT AU GESTIONNAIRE DU PERSONNEL AVANT LE | L5: 45300
B6: = Zones de saisie informatique svp
B7: = Zones de saisie manuscrite svp
A8: Nom : | C8: jayat | H8: Région / Exploit. : | K8: Sud Ouest / Laroque d'Olmes
A10: Prénom : | C10: Emilie | H10: Statut / Emploi : | K10: REX
A13: Date | D13: Périodes d'Astreinte niveau 1 | F13: Type d'astreinte A B C ou D | H13: Heure de début d'astreinte le 1er jour | K13: Heure de fin d'astreinte le dernier jour | M13: Commentaires / remarques
A14: 45264
A15: 45265
A16: 45266
A17: 45267
A18: 45268
A19: 45269
A20: 45270
A21: 45271
A22: 45272
A23: 45273
A24: 45274
A25: 45275
... A48: 45298
A49: TOTAL DE LA PERIODE | D49: =+COUNTA(D14:E48) -> 0 | F49: =+COUNTA(F14:G48) -> 0
D50: jours de niveau 1
A52: Je certifie l'exactitude de toutes les données renseignées.
A53: Fait le : | C53: =TODAY() -> 45320 | J53: Nom / Prénom de la hiérarchie :
B54: Signature du Collaborateur : | J54: Signature de la Hiérarchie après contrôles :
A60: Fiche à conserver durant 3 ans | J60: Fiche à retourner à votre Gestionnaire du Personnel

Sheet Niveau 2 Janv
D2: ASTREINTE niveau 2 | L2: ='Niveau 1 Janv'!L2:N4 -> 45292
B5: RETOUR DU PRESENT DOCUMENT AU GESTIONNAIRE DU PERSONNEL AVANT LE | L5: =+'Niveau 1 Janv'!L5:N5 -> 45300
B6: = Zones de saisie informatique svp
B7: = Zones de saisie manuscrite svp
A8: Nom : | H8: Région / Exploit. :
A10: Prénom : | H10: Statut / Emploi :
A12: Type d'astreinte | H12: Heure de début : | M12: le 1er jour
H13: Heure de fin : | M13: le dernier jour
F15: INTERVENTION PHYSIQUE
A16: Date | D16: Périodes d'Astreinte niveau 2 | F16: Où et pour quel motif ? | H16: Temps trajet domicile | J16: Heure début intervention | K16: Heure fin d'intervention | M16: Quelle durée d'intervention ?
A17: 45264 | M17: =+K17-J17 -> 0
A18: 45265 | M18: =+K18-J18 -> 0
A19: 45266 | M19: =+K19-J19 -> 0
A20: 45267 | M20: =+K20-J20 -> 0
A21: 45268 | M21: =+K21-J21 -> 0
A22: 45269 | M22: =+K22-J22 -> 0
A23: 45270 | M23: =+K23-J23 -> 0
A24: 45271 | M24: =+K24-J24 -> 0
A25: 45272 | M25: =+K25-J25 -> 0
A26: 45273 | M26: =+K26-J26 -> 0
A27: 45274 | M27: =+K27-J27 -> 0
A28: 45275 | M28: =+K28-J28 -> 0
... A51: 45298 | M51: =+K51-J51 -> 0
A52: TOTAL DE LA PERIODE | D52: =+COUNTA(D17:E51) -> 0 | F52: =+COUNTA(F17:G51) -> 0 | H52: =SUM(H17:I51) -> 0 | M52: =+SUM(M17:O51) -> 0
D53: jours | F53: interventions | H53: heures | M53: h d'interventions
A55: En cas d'intervention sur le terrain, quel moyen de transport avez-vous utilisé ? | J55: Véhicule de service ou fonction =
J56: Véhicule personnel (NDF à établir) =
A57: Je certifie l'exactitude de toutes les données renseignées.
A58: Fait le : | C58: =TODAY() -> 45320 | J58: Nom / Prénom de la hiérarchie :
B59: Signature du Collaborateur : | J59: Signature de la Hiérarchie après contrôles :
A65: Fiche à conserver durant 3 ans | J65: Fiche à retourner à votre Gestionnaire du Personnel

Sheet Mixte Janv
D2: ASTREINTE MIXTE | L2: ='Niveau 1 Janv'!L2:N4 -> 45292
B5: RETOUR DU PRESENT DOCUMENT AU GESTIONNAIRE DU PERSONNEL AVANT LE | L5: =+'Niveau 2 Janv'!L5:N5 -> 45300
B6: = Zones de saisie informatique svp
B7: = Zones de saisie manuscrite svp
A8: Nom : | H8: Région / Exploit. :
A10: Prénom : | H10: Statut / Emploi :
A12: Type d'astreinte | C12: A ou B ou C ou D | H12: Heure de début : | M12: le 1er jour
H13: Heure de fin : | M13: le dernier jour
A14: Type de rémunération : niveau 1
F15: INTERVENTION PHYSIQUE
A16: Date | D16: Périodes d'Astreinte niveau 2 | F16: Où et pour quel motif ? | H16: Temps trajet domicile | J16: Heure début intervention | K16: Heure fin d'intervention | M16: Quelle durée d'intervention ?
A17: 45264 | M17: =+K17-J17 -> 0
A18: 45265 | M18: =+K18-J18 -> 0
A19: 45266 | M19: =+K19-J19 -> 0
A20: 45267 | M20: =+K20-J20 -> 0
A21: 45268 | M21: =+K21-J21 -> 0
A22: 45269 | M22: =+K22-J22 -> 0
A23: 45270 | M23: =+K23-J23 -> 0
A24: 45271 | M24: =+K24-J24 -> 0
A25: 45272 | M25: =+K25-J25 -> 0
A26: 45273 | M26: =+K26-J26 -> 0
A27: 45274 | M27: =+K27-J27 -> 0
A28: 45275 | M28: =+K28-J28 -> 0
... A51: 45298 | M51: =+K51-J51 -> 0
A52: TOTAL DE LA PERIODE | D52: =+COUNTA(D17:E51) -> 0 | F52: =+COUNTA(F17:G51) -> 0 | H52: =SUM(H17:I51) -> 0 | M52: =+SUM(M17:O51) -> 0
D53: jours | F53: interventions | H53: heures | M53: h d'interventions
A55: En cas d'intervention sur le terrain, quel moyen de transport avez-vous utilisé ? | J55: Véhicule de service ou fonction =
J56: Véhicule personnel (NDF à établir) =
A57: Je certifie l'exactitude de toutes les données renseignées.
A58: Fait le : | C58: =TODAY() -> 45320 | J58: Nom / Prénom de la hiérarchie :
B59: Signature du Collaborateur : | J59: Signature de la Hiérarchie après contrôles :
A65: Fiche à conserver durant 3 ans | J65: Fiche à retourner à votre Gestionnaire du Personnel

Sheet Niveau 1 Fév
D2: ASTREINTE niveau 1 | L2: 45323
B5: RETOUR DU PRESENT DOCUMENT AU GESTIONNAIRE DU PERSONNEL AVANT LE | L5: 45328
B6: = Zones de saisie informatique svp
B7: = Zones de saisie manuscrite svp
A8: Nom : | C8: jayat | H8: Région / Exploit. : | K8: Sud Ouest / Laroque d'olmes
A10: Prénom : | C10: Emilie | H10: Statut / Emploi : | K10: Rex
A13: Date | D13: Périodes d'Astreinte niveau 1 | F13: Type d'astreinte A B C ou D | H13: Heure de début d'astreinte le 1er jour | K13: Heure de fin d'astreinte le dernier jour | M13: Commentaires / remarques
A14: 45299
A15: 45300
A16: 45301
A17: 45302
A18: 45303
A19: 45304
A20: 45305
A21: 45306
A22: 45307
A23: 45308
A24: 45309
A25: 45310
... A41: 45326
A42: TOTAL DE LA PERIODE | D42: =+COUNTA(D14:E41) -> 0 | F42: =+COUNTA(F14:G41) -> 0
D43: jours de niveau 1
A45: Je certifie l'exactitude de toutes les données renseignées.
A46: Fait le : | C46: =TODAY() -> 45320 | J46: Nom / Prénom de la hiérarchie :
B47: Signature du Collaborateur : | J47: Signature de la Hiérarchie après contrôles :
A53: Fiche à conserver durant 3 ans | J53: Fiche à retourner à votre Gestionnaire du Personnel

Sheet Niveau 2 Fév
D2: ASTREINTE niveau 2 | L2: ='Niveau 1 Fév'!L2:N4 -> 45323
B5: RETOUR DU PRESENT DOCUMENT AU GESTIONNAIRE DU PERSONNEL AVANT LE | L5: =+'Niveau 1 Fév'!L5:N5 -> 45328
B6: = Zones de saisie informatique svp
B7: = Zones de saisie manuscrite svp
A8: Nom : | H8: Région / Exploit. :
A10: Prénom : | H10: Statut / Emploi :
A12: Type d'astreinte | H12: Heure de début : | M12: le 1er jour
H13: Heure de fin : | M13: le dernier jour
F15: INTERVENTION PHYSIQUE
A16: Date | D16: Périodes d'Astreinte niveau 2 | F16: Où et pour quel motif ? | H16: Temps trajet domicile | J16: Heure début intervention | K16: Heure fin d'intervention | M16: Quelle durée d'intervention ?
A17: 45299 | M17: =+K17-J17 -> 0
A18: 45300 | M18: =+K18-J18 -> 0
A19: 45301 | M19: =+K19-J19 -> 0
A20: 45302 | M20: =+K20-J20 -> 0
A21: 45303 | M21: =+K21-J21 -> 0
A22: 45304 | M22: =+K22-J22 -> 0
A23: 45305 | M23: =+K23-J23 -> 0
A24: 45306 | M24: =+K24-J24 -> 0
A25: 45307 | M25: =+K25-J25 -> 0
A26: 45308 | M26: =+K26-J26 -> 0
A27: 45309 | M27: =+K27-J27 -> 0
A28: 45310 | M28: =+K28-J28 -> 0
... A44: 45326 | M44: =+K44-J44 -> 0
A45: TOTAL DE LA PERIODE | D45: =+COUNTA(D17:E44) -> 0 | F45: =+COUNTA(F17:G44) -> 0 | H45: =SUM(H17:I44) -> 0 | M45: =+SUM(M17:O44) -> 0
D46: jours | F46: interventions | H46: heures | M46: h d'interventions
A48: En cas d'intervention sur le terrain, quel moyen de transport avez-vous utilisé ? | J48: Véhicule de service ou fonction =
J49: Véhicule personnel (NDF à établir) =
A50: Je certifie l'exactitude de toutes les données renseignées.
A51: Fait le : | C51: =TODAY() -> 45320 | J51: Nom / Prénom de la hiérarchie :
B52: Signature du Collaborateur : | J52: Signature de la Hiérarchie après contrôles :
A58: Fiche à conserver durant 3 ans | J58: Fiche à retourner à votre Gestionnaire du Personnel

Sheet Mixte Fév
D2: ASTREINTE MIXTE | L2: ='Niveau 1 Fév'!L2:N4 -> 45323
B5: RETOUR DU PRESENT DOCUMENT AU GESTIONNAIRE DU PERSONNEL AVANT LE | L5: =+'Niveau 2 Fév'!L5:N5 -> 45328
B6: = Zones de saisie informatique svp
B7: = Zones de saisie manuscrite svp
A8: Nom : | H8: Région / Exploit. :
A10: Prénom : | H10: Statut / Emploi :
A12: Type d'astreinte | C12: A ou B ou C ou D | H12: Heure de début : | M12: le 1er jour
H13: Heure de fin : | M13: le dernier jour
A14: Type de rémunération : niveau 1
F15: INTERVENTION PHYSIQUE
A16: Date | D16: Périodes d'Astreinte niveau 2 | F16: Où et pour quel motif ? | H16: Temps trajet domicile | J16: Heure début intervention | K16: Heure fin d'intervention | M16: Quelle durée d'intervention ?
A17: 45299 | M17: =+K17-J17 -> 0
A18: 45300 | M18: =+K18-J18 -> 0
A19: 45301 | M19: =+K19-J19 -> 0
A20: 45302 | M20: =+K20-J20 -> 0
A21: 45303 | M21: =+K21-J21 -> 0
A22: 45304 | M22: =+K22-J22 -> 0
A23: 45305 | M23: =+K23-J23 -> 0
A24: 45306 | M24: =+K24-J24 -> 0
A25: 45307 | M25: =+K25-J25 -> 0
A26: 45308 | M26: =+K26-J26 -> 0
A27: 45309 | M27: =+K27-J27 -> 0
A28: 45310 | M28: =+K28-J28 -> 0
... A44: 45326 | M44: =+K44-J44 -> 0
A45: TOTAL DE LA PERIODE | D45: =+COUNTA(D17:E44) -> 0 | F45: =+COUNTA(F17:G44) -> 0 | H45: =SUM(H17:I44) -> 0 | M45: =+SUM(M17:O44) -> 0
D46: jours | F46: interventions | H46: heures | M46: h d'interventions
A48: En cas d'intervention sur le terrain, quel moyen de transport avez-vous utilisé ? | J48: Véhicule de service ou fonction =
J49: Véhicule personnel (NDF à établir) =
A50: Je certifie l'exactitude de toutes les données renseignées.
A51: Fait le : | C51: =TODAY() -> 45320 | J51: Nom / Prénom de la hiérarchie :
B52: Signature du Collaborateur : | J52: Signature de la Hiérarchie après contrôles :
A58: Fiche à conserver durant 3 ans | J58: Fiche à retourner à votre Gestionnaire du Personnel

Sheet Niveau 1 Mars
D2: ASTREINTE niveau 1 | L2: 45352
B5: RETOUR DU PRESENT DOCUMENT AU GESTIONNAIRE DU PERSONNEL AVANT LE | L5: 45356
B6: = Zones de saisie informatique svp
B7: = Zones de saisie manuscrite svp
A8: Nom : | H8: Région / Exploit. :
A10: Prénom : | H10: Statut / Emploi :
A13: Date | D13: Périodes d'Astreinte niveau 1 | F13: Type d'astreinte A B C ou D | H13: Heure de début d'astreinte le 1er jour | K13: Heure de fin d'astreinte le dernier jour | M13: Commentaires / remarques
A14: 45327
A15: 45328
A16: 45329
A17: 45330
A18: 45331
A19: 45332
A20: 45333
A21: 45334
A22: 45335
A23: 45336
A24: 45337
A25: 45338
... A41: 45354
A42: TOTAL DE LA PERIODE | D42: =+COUNTA(D14:E41) -> 0 | F42: =+COUNTA(F14:G41) -> 0
D43: jours de niveau 1
A45: Je certifie l'exactitude de toutes les données renseignées.
A46: Fait le : | C46: =TODAY() -> 45320 | J46: Nom / Prénom de la hiérarchie :
B47: Signature du Collaborateur : | J47: Signature de la Hiérarchie après contrôles :
A53: Fiche à conserver durant 3 ans | J53: Fiche à retourner à votre Gestionnaire du Personnel

Sheet Niveau 2 Mars
D2: ASTREINTE niveau 2 | L2: ='Niveau 1 Mars'!L2:N4 -> 45352
B5: RETOUR DU PRESENT DOCUMENT AU GESTIONNAIRE DU PERSONNEL AVANT LE | L5: =+'Niveau 1 Mars'!L5:N5 -> 45356
B6: = Zones de saisie informatique svp
B7: = Zones de saisie manuscrite svp
A8: Nom : | H8: Région / Exploit. :
A10: Prénom : | H10: Statut / Emploi :
A12: Type d'astreinte | H12: Heure de début : | M12: le 1er jour
H13: Heure de fin : | M13: le dernier jour
F15: INTERVENTION PHYSIQUE
A16: Date | D16: Périodes d'Astreinte niveau 2 | F16: Où et pour quel motif ? | H16: Temps trajet domicile | J16: Heure début intervention | K16: Heure fin d'intervention | M16: Quelle durée d'intervention ?
A17: 45327 | M17: =+K17-J17 -> 0
A18: 45328 | M18: =+K18-J18 -> 0
A19: 45329 | M19: =+K19-J19 -> 0
A20: 45330 | M20: =+K20-J20 -> 0
A21: 45331 | M21: =+K21-J21 -> 0
A22: 45332 | M22: =+K22-J22 -> 0
A23: 45333 | M23: =+K23-J23 -> 0
A24: 45334 | M24: =+K24-J24 -> 0
A25: 45335 | M25: =+K25-J25 -> 0
A26: 45336 | M26: =+K26-J26 -> 0
A27: 45337 | M27: =+K27-J27 -> 0
A28: 45338 | M28: =+K28-J28 -> 0
... A44: 45354 | M44: =+K44-J44 -> 0
A45: TOTAL DE LA PERIODE | D45: =+COUNTA(D17:E44) -> 0 | F45: =+COUNTA(F17:G44) -> 0 | H45: =SUM(H17:I44) -> 0 | M45: =+SUM(M17:O44) -> 0
D46: jours | F46: interventions | H46: heures | M46: h d'interventions
A48: En cas d'intervention sur le terrain, quel moyen de transport avez-vous utilisé ? | J48: Véhicule de service ou fonction =
J49: Véhicule personnel (NDF à établir) =
A50: Je certifie l'exactitude de toutes les données renseignées.
A51: Fait le : | C51: =TODAY() -> 45320 | J51: Nom / Prénom de la hiérarchie :
B52: Signature du Collaborateur : | J52: Signature de la Hiérarchie après contrôles :
A58: Fiche à conserver durant 3 ans | J58: Fiche à retourner à votre Gestionnaire du Personnel

Sheet Mixte Mars
D2: ASTREINTE MIXTE | L2: ='Niveau 1 Mars'!L2:N4 -> 45352
B5: RETOUR DU PRESENT DOCUMENT AU GESTIONNAIRE DU PERSONNEL AVANT LE | L5: =+'Niveau 2 Mars'!L5:N5 -> 45356
B6: = Zones de saisie informatique svp
B7: = Zones de saisie manuscrite svp
A8: Nom : | H8: Région / Exploit. :
A10: Prénom : | H10: Statut / Emploi :
A12: Type d'astreinte | C12: A ou B ou C ou D | H12: Heure de début : | M12: le 1er jour
H13: Heure de fin : | M13: le dernier jour
A14: Type de rémunération : niveau 1
F15: INTERVENTION PHYSIQUE
A16: Date | D16: Périodes d'Astreinte niveau 2 | F16: Où et pour quel motif ? | H16: Temps trajet domicile | J16: Heure début intervention | K16: Heure fin d'intervention | M16: Quelle durée d'intervention ?
A17: 45327 | M17: =+K17-J17 -> 0
A18: 45328 | M18: =+K18-J18 -> 0
A19: 45329 | M19: =+K19-J19 -> 0
A20: 45330 | M20: =+K20-J20 -> 0
A21: 45331 | M21: =+K21-J21 -> 0
A22: 45332 | M22: =+K22-J22 -> 0
A23: 45333 | M23: =+K23-J23 -> 0
A24: 45334 | M24: =+K24-J24 -> 0
A25: 45335 | M25: =+K25-J25 -> 0
A26: 45336 | M26: =+K26-J26 -> 0
A27: 45337 | M27: =+K27-J27 -> 0
A28: 45338 | M28: =+K28-J28 -> 0
... A44: 45354 | M44: =+K44-J44 -> 0
A45: TOTAL DE LA PERIODE | D45: =+COUNTA(D17:E44) -> 0 | F45: =+COUNTA(F17:G44) -> 0 | H45: =SUM(H17:I44) -> 0 | M45: =+SUM(M17:O44) -> 0
D46: jours | F46: interventions | H46: heures | M46: h d'interventions
A48: En cas d'intervention sur le terrain, quel moyen de transport avez-vous utilisé ? | J48: Véhicule de service ou fonction =
J49: Véhicule personnel (NDF à établir) =
A50: Je certifie l'exactitude de toutes les données renseignées.
A51: Fait le : | C51: =TODAY() -> 45320 | J51: Nom / Prénom de la hiérarchie :
B52: Signature du Collaborateur : | J52: Signature de la Hiérarchie après contrôles :
A58: Fiche à conserver durant 3 ans | J58: Fiche à retourner à votre Gestionnaire du Personnel

Sheet Niveau 1 Avril
D2: ASTREINTE niveau 1 | L2: 45383
B5: RETOUR DU PRESENT DOCUMENT AU GESTIONNAIRE DU PERSONNEL AVANT LE | L5: 45384
B6: = Zones de saisie informatique svp
B7: = Zones de saisie manuscrite svp
A8: Nom : | H8: Région / Exploit. :
A10: Prénom : | H10: Statut / Emploi :
A13: Date | D13: Périodes d'Astreinte niveau 1 | F13: Type d'astreinte A B C ou D | H13: Heure de début d'astreinte le 1er jour | K13: Heure de fin d'astreinte le dernier jour | M13: Commentaires / remarques
A14: 45355
A15: 45356
A16: 45357
A17: 45358
A18: 45359
A19: 45360
A20: 45361
A21: 45362
A22: 45363
A23: 45364
A24: 45365
A25: 45366
... A41: 45382
A42: TOTAL DE LA PERIODE | D42: =+COUNTA(D14:E41) -> 0 | F42: =+COUNTA(F14:G41) -> 0
D43: jours de niveau 1
A45: Je certifie l'exactitude de toutes les données renseignées.
A46: Fait le : | C46: =TODAY() -> 45320 | J46: Nom / Prénom de la hiérarchie :
B47: Signature du Collaborateur : | J47: Signature de la Hiérarchie après contrôles :
A53: Fiche à conserver durant 3 ans | J53: Fiche à retourner à votre Gestionnaire du Personnel

Sheet Niveau 2 Avril
D2: ASTREINTE niveau 2 | L2: ='Niveau 1 Avril'!L2:N4 -> 45383
B5: RETOUR DU PRESENT DOCUMENT AU GESTIONNAIRE DU PERSONNEL AVANT LE | L5: =+'Niveau 1 Avril'!L5:N5 -> 45384
B6: = Zones de saisie informatique svp
B7: = Zones de saisie manuscrite svp
A8: Nom : | H8: Région / Exploit. :
A10: Prénom : | H10: Statut / Emploi :
A12: Type d'astreinte | H12: Heure de début : | M12: le 1er jour
H13: Heure de fin : | M13: le dernier jour
F15: INTERVENTION PHYSIQUE
A16: Date | D16: Périodes d'Astreinte niveau 2 | F16: Où et pour quel motif ? | H16: Temps trajet domicile | J16: Heure début intervention | K16: Heure fin d'intervention | M16: Quelle durée d'intervention ?
A17: 45355 | M17: =+K17-J17 -> 0
A18: 45356 | M18: =+K18-J18 -> 0
A19: 45357 | M19: =+K19-J19 -> 0
A20: 45358 | M20: =+K20-J20 -> 0
A21: 45359 | M21: =+K21-J21 -> 0
A22: 45360 | M22: =+K22-J22 -> 0
A23: 45361 | M23: =+K23-J23 -> 0
A24: 45362 | M24: =+K24-J24 -> 0
A25: 45363 | M25: =+K25-J25 -> 0
A26: 45364 | M26: =+K26-J26 -> 0
A27: 45365 | M27: =+K27-J27 -> 0
A28: 45366 | M28: =+K28-J28 -> 0
... A44: 45382 | M44: =+K44-J44 -> 0
A45: TOTAL DE LA PERIODE | D45: =+COUNTA(D17:E44) -> 0 | F45: =+COUNTA(F17:G44) -> 0 | H45: =SUM(H17:I44) -> 0 | M45: =+SUM(M17:O44) -> 0
D46: jours | F46: interventions | H46: heures | M46: h d'interventions
A48: En cas d'intervention sur le terrain, quel moyen de transport avez-vous utilisé ? | J48: Véhicule de service ou fonction =
J49: Véhicule personnel (NDF à établir) =
A50: Je certifie l'exactitude de toutes les données renseignées.
A51: Fait le : | C51: =TODAY() -> 45320 | J51: Nom / Prénom de la hiérarchie :
B52: Signature du Collaborateur : | J52: Signature de la Hiérarchie après contrôles :
A58: Fiche à conserver durant 3 ans | J58: Fiche à retourner à votre Gestionnaire du Personnel

Sheet Mixte Avril
D2: ASTREINTE MIXTE | L2: ='Niveau 1 Avril'!L2:N4 -> 45383
B5: RETOUR DU PRESENT DOCUMENT AU GESTIONNAIRE DU PERSONNEL AVANT LE | L5: =+'Niveau 2 Avril'!L5:N5 -> 45384
B6: = Zones de saisie informatique svp
B7: = Zones de saisie manuscrite svp
A8: Nom : | H8: Région / Exploit. :
A10: Prénom : | H10: Statut / Emploi :
A12: Type d'astreinte | C12: A ou B ou C ou D | H12: Heure de début : | M12: le 1er jour
H13: Heure de fin : | M13: le dernier jour
A14: Type de rémunération : niveau 1
F15: INTERVENTION PHYSIQUE
A16: Date | D16: Périodes d'Astreinte niveau 2 | F16: Où et pour quel motif ? | H16: Temps trajet domicile | J16: Heure début intervention | K16: Heure fin d'intervention | M16: Quelle durée d'intervention ?
A17: 45355 | M17: =+K17-J17 -> 0
A18: 45356 | M18: =+K18-J18 -> 0
A19: 45357 | M19: =+K19-J19 -> 0
A20: 45358 | M20: =+K20-J20 -> 0
A21: 45359 | M21: =+K21-J21 -> 0
A22: 45360 | M22: =+K22-J22 -> 0
A23: 45361 | M23: =+K23-J23 -> 0
A24: 45362 | M24: =+K24-J24 -> 0
A25: 45363 | M25: =+K25-J25 -> 0
A26: 45364 | M26: =+K26-J26 -> 0
A27: 45365 | M27: =+K27-J27 -> 0
A28: 45366 | M28: =+K28-J28 -> 0
... A44: 45382 | M44: =+K44-J44 -> 0
A45: TOTAL DE LA PERIODE | D45: =+COUNTA(D17:E44) -> 0 | F45: =+COUNTA(F17:G44) -> 0 | H45: =SUM(H17:I44) -> 0 | M45: =+SUM(M17:O44) -> 0
D46: jours | F46: interventions | H46: heures | M46: h d'interventions
A48: En cas d'intervention sur le terrain, quel moyen de transport avez-vous utilisé ? | J48: Véhicule de service ou fonction =
J49: Véhicule personnel (NDF à établir) =
A50: Je certifie l'exactitude de toutes les données renseignées.
A51: Fait le : | C51: =TODAY() -> 45320 | J51: Nom / Prénom de la hiérarchie :
B52: Signature du Collaborateur : | J52: Signature de la Hiérarchie après contrôles :
A58: Fiche à conserver durant 3 ans | J58: Fiche à retourner à votre Gestionnaire du Personnel

Sheet Niveau 1 Mai
D2: ASTREINTE niveau 1 | L2: 45413
B5: RETOUR DU PRESENT DOCUMENT AU GESTIONNAIRE DU PERSONNEL AVANT LE | L5: 45412
B6: = Zones de saisie informatique svp
B7: = Zones de saisie manuscrite svp
A8: Nom : | H8: Région / Exploit. :
A10: Prénom : | H10: Statut / Emploi :
A13: Date | D13: Périodes d'Astreinte niveau 1 | F13: Type d'astreinte A B C ou D | H13: Heure de début d'astreinte le 1er jour | K13: Heure de fin d'astreinte le dernier jour | M13: Commentaires / remarques
A14: 45383
A15: 45384
A16: 45385
A17: 45386
A18: 45387
A19: 45388
A20: 45389
A21: 45390
A22: 45391
A23: 45392
A24: 45393
A25: 45394
... A41: 45410
A42: TOTAL DE LA PERIODE | D42: =+COUNTA(D14:E41) -> 0 | F42: =+COUNTA(F14:G41) -> 0
D43: jours de niveau 1
A45: Je certifie l'exactitude de toutes les données renseignées.
A46: Fait le : | C46: =TODAY() -> 45320 | J46: Nom / Prénom de la hiérarchie :
B47: Signature du Collaborateur : | J47: Signature de la Hiérarchie après contrôles :
A53: Fiche à conserver durant 3 ans | J53: Fiche à retourner à votre Gestionnaire du Personnel

Sheet Niveau 2 Mai
D2: ASTREINTE niveau 2 | L2: ='Niveau 1 Mai'!L2:N4 -> 45413
B5: RETOUR DU PRESENT DOCUMENT AU GESTIONNAIRE DU PERSONNEL AVANT LE | L5: =+'Niveau 1 Mai'!L5:N5 -> 45412
B6: = Zones de saisie informatique svp
B7: = Zones de saisie manuscrite svp
A8: Nom : | H8: Région / Exploit. :
A10: Prénom : | H10: Statut / Emploi :
A12: Type d'astreinte | H12: Heure de début : | M12: le 1er jour
H13: Heure de fin : | M13: le dernier jour
F15: INTERVENTION PHYSIQUE
A16: Date | D16: Périodes d'Astreinte niveau 2 | F16: Où et pour quel motif ? | H16: Temps trajet domicile | J16: Heure début intervention | K16: Heure fin d'intervention | M16: Quelle durée d'intervention ?
A17: 45383 | M17: =+K17-J17 -> 0
A18: 45384 | M18: =+K18-J18 -> 0
A19: 45385 | M19: =+K19-J19 -> 0
A20: 45386 | M20: =+K20-J20 -> 0
A21: 45387 | M21: =+K21-J21 -> 0
A22: 45388 | M22: =+K22-J22 -> 0
A23: 45389 | M23: =+K23-J23 -> 0
A24: 45390 | M24: =+K24-J24 -> 0
A25: 45391 | M25: =+K25-J25 -> 0
A26: 45392 | M26: =+K26-J26 -> 0
A27: 45393 | M27: =+K27-J27 -> 0
A28: 45394 | M28: =+K28-J28 -> 0
... A44: 45410 | M44: =+K44-J44 -> 0
A45: TOTAL DE LA PERIODE | D45: =+COUNTA(D17:E44) -> 0 | F45: =+COUNTA(F17:G44) -> 0 | H45: =SUM(H17:I44) -> 0 | M45: =+SUM(M17:O44) -> 0
D46: jours | F46: interventions | H46: heures | M46: h d'interventions
A48: En cas d'intervention sur le terrain, quel moyen de transport avez-vous utilisé ? | J48: Véhicule de service ou fonction =
J49: Véhicule personnel (NDF à établir) =
A50: Je certifie l'exactitude de toutes les données renseignées.
A51: Fait le : | C51: =TODAY() -> 45320 | J51: Nom / Prénom de la hiérarchie :
B52: Signature du Collaborateur : | J52: Signature de la Hiérarchie après contrôles :
A58: Fiche à conserver durant 3 ans | J58: Fiche à retourner à votre Gestionnaire du Personnel

Sheet Mixte Mai
D2: ASTREINTE MIXTE | L2: ='Niveau 1 Mai'!L2:N4 -> 45413
B5: RETOUR DU PRESENT DOCUMENT AU GESTIONNAIRE DU PERSONNEL AVANT LE | L5: =+'Niveau 1 Mai'!L5:N5 -> 45412
B6: = Zones de saisie informatique svp
B7: = Zones de saisie manuscrite svp
A8: Nom : | H8: Région / Exploit. :
A10: Prénom : | H10: Statut / Emploi :
A12: Type d'astreinte | C12: A ou B ou C ou D | H12: Heure de début : | M12: le 1er jour
H13: Heure de fin : | M13: le dernier jour
A14: Type de rémunération : niveau 1
F15: INTERVENTION PHYSIQUE
A16: Date | D16: Périodes d'Astreinte niveau 2 | F16: Où et pour quel motif ? | H16: Temps trajet domicile | J16: Heure début intervention | K16: Heure fin d'intervention | M16: Quelle durée d'intervention ?
A17: 45383 | M17: =+K17-J17 -> 0
A18: 45384 | M18: =+K18-J18 -> 0
A19: 45385 | M19: =+K19-J19 -> 0
A20: 45386 | M20: =+K20-J20 -> 0
A21: 45387 | M21: =+K21-J21 -> 0
A22: 45388 | M22: =+K22-J22 -> 0
A23: 45389 | M23: =+K23-J23 -> 0
A24: 45390 | M24: =+K24-J24 -> 0
A25: 45391 | M25: =+K25-J25 -> 0
A26: 45392 | M26: =+K26-J26 -> 0
A27: 45393 | M27: =+K27-J27 -> 0
A28: 45394 | M28: =+K28-J28 -> 0
... A44: 45410 | M44: =+K44-J44 -> 0
A45: TOTAL DE LA PERIODE | D45: =+COUNTA(D17:E44) -> 0 | F45: =+COUNTA(F17:G44) -> 0 | H45: =SUM(H17:I44) -> 0 | M45: =+SUM(M17:O44) -> 0
D46: jours | F46: interventions | H46: heures | M46: h d'interventions
A48: En cas d'intervention sur le terrain, quel moyen de transport avez-vous utilisé ? | J48: Véhicule de service ou fonction =
J49: Véhicule personnel (NDF à établir) =
A50: Je certifie l'exactitude de toutes les données renseignées.
A51: Fait le : | C51: =TODAY() -> 45320 | J51: Nom / Prénom de la hiérarchie :
B52: Signature du Collaborateur : | J52: Signature de la Hiérarchie après contrôles :
A58: Fiche à conserver durant 3 ans | J58: Fiche à retourner à votre Gestionnaire du Personnel

Sheet Niveau 1 Juin
D2: ASTREINTE niveau 1 | L2: 45444
B5: RETOUR DU PRESENT DOCUMENT AU GESTIONNAIRE DU PERSONNEL AVANT LE | L5: 45440
B6: = Zones de saisie informatique svp
B7: = Zones de saisie manuscrite svp
A8: Nom : | H8: Région / Exploit. :
A10: Prénom : | H10: Statut / Emploi :
A13: Date | D13: Périodes d'Astreinte niveau 1 | F13: Type d'astreinte A B C ou D | H13: Heure de début d'astreinte le 1er jour | K13: Heure de fin d'astreinte le dernier jour | M13: Commentaires / remarques
A14: 45411
A15: 45412
A16: 45413
A17: 45414
A18: 45415
A19: 45416
A20: 45417
A21: 45418
A22: 45419
A23: 45420
A24: 45421
A25: 45422
... A41: 45438
A42: TOTAL DE LA PERIODE | D42: =+COUNTA(D14:E41) -> 0 | F42: =+COUNTA(F14:G41) -> 0
D43: jours de niveau 1
A49: Je certifie l'exactitude de toutes les données renseignées.
A50: Fait le : | C50: =TODAY() -> 45320 | J50: Nom / Prénom de la hiérarchie :
B51: Signature du Collaborateur : | J51: Signature de la Hiérarchie après contrôles :
A57: Fiche à conserver durant 3 ans | J57: Fiche à retourner à votre Gestionnaire du Personnel

Sheet Niveau 2 Juin
D2: ASTREINTE niveau 2 | L2: ='Niveau 1 Juin'!L2:N4 -> 45444
B5: RETOUR DU PRESENT DOCUMENT AU GESTIONNAIRE DU PERSONNEL AVANT LE | L5: =+'Niveau 1 Juin'!L5:N5 -> 45440
B6: = Zones de saisie informatique svp
B7: = Zones de saisie manuscrite svp
A8: Nom : | H8: Région / Exploit. :
A10: Prénom : | H10: Statut / Emploi :
A12: Type d'astreinte | H12: Heure de début : | M12: le 1er jour
H13: Heure de fin : | M13: le dernier jour
F15: INTERVENTION PHYSIQUE
A16: Date | D16: Périodes d'Astreinte niveau 2 | F16: Où et pour quel motif ? | H16: Temps trajet domicile | J16: Heure début intervention | K16: Heure fin d'intervention | M16: Quelle durée d'intervention ?
A17: 45411 | M17: =+K17-J17 -> 0
A18: 45412 | M18: =+K18-J18 -> 0
A19: 45413 | M19: =+K19-J19 -> 0
A20: 45414 | M20: =+K20-J20 -> 0
A21: 45415 | M21: =+K21-J21 -> 0
A22: 45416 | M22: =+K22-J22 -> 0
A23: 45417 | M23: =+K23-J23 -> 0
A24: 45418 | M24: =+K24-J24 -> 0
A25: 45419 | M25: =+K25-J25 -> 0
A26: 45420 | M26: =+K26-J26 -> 0
A27: 45421 | M27: =+K27-J27 -> 0
A28: 45422 | M28: =+K28-J28 -> 0
... A44: 45438 | M44: =+K44-J44 -> 0
A45: TOTAL DE LA PERIODE | D45: =+COUNTA(D17:E44) -> 0 | F45: =+COUNTA(F17:G44) -> 0 | H45: =SUM(H17:I44) -> 0 | M45: =+SUM(M17:O44) -> 0
D46: jours | F46: interventions | H46: heures | M46: h d'interventions
A51: En cas d'intervention sur le terrain, quel moyen de transport avez-vous utilisé ? | J51: Véhicule de service ou fonction =
J52: Véhicule personnel (NDF à établir) =
A53: Je certifie l'exactitude de toutes les données renseignées.
A54: Fait le : | C54: =TODAY() -> 45320 | J54: Nom / Prénom de la hiérarchie :
B55: Signature du Collaborateur : | J55: Signature de la Hiérarchie après contrôles :
A61: Fiche à conserver durant 3 ans | J61: Fiche à retourner à votre Gestionnaire du Personnel

Sheet Mixte Juin
D2: ASTREINTE MIXTE | L2: ='Niveau 1 Juin'!L2:N4 -> 45444
B5: RETOUR DU PRESENT DOCUMENT AU GESTIONNAIRE DU PERSONNEL AVANT LE | L5: =+'Niveau 1 Juin'!L5:N5 -> 45440
B6: = Zones de saisie informatique svp
B7: = Zones de saisie manuscrite svp
A8: Nom : | H8: Région / Exploit. :
A10: Prénom : | H10: Statut / Emploi :
A12: Type d'astreinte | C12: A ou B ou C ou D | H12: Heure de début : | M12: le 1er jour
H13: Heure de fin : | M13: le dernier jour
A14: Type de rémunération : niveau 1
F15: INTERVENTION PHYSIQUE
A16: Date | D16: Périodes d'Astreinte niveau 2 | F16: Où et pour quel motif ? | H16: Temps trajet domicile | J16: Heure début intervention | K16: Heure fin d'intervention | M16: Quelle durée d'intervention ?
A17: 45411 | M17: =+K17-J17 -> 0
A18: 45412 | M18: =+K18-J18 -> 0
A19: 45413 | M19: =+K19-J19 -> 0
A20: 45414 | M20: =+K20-J20 -> 0
A21: 45415 | M21: =+K21-J21 -> 0
A22: 45416 | M22: =+K22-J22 -> 0
A23: 45417 | M23: =+K23-J23 -> 0
A24: 45418 | M24: =+K24-J24 -> 0
A25: 45419 | M25: =+K25-J25 -> 0
A26: 45420 | M26: =+K26-J26 -> 0
A27: 45421 | M27: =+K27-J27 -> 0
A28: 45422 | M28: =+K28-J28 -> 0
... A44: 45438 | M44: =+K44-J44 -> 0
A45: TOTAL DE LA PERIODE | D45: =+COUNTA(D17:E44) -> 0 | F45: =+COUNTA(F17:G44) -> 0 | H45: =SUM(H17:I44) -> 0 | M45: =+SUM(M17:O44) -> 0
D46: jours | F46: interventions | H46: heures | M46: h d'interventions
A53: En cas d'intervention sur le terrain, quel moyen de transport avez-vous utilisé ? | J53: Véhicule de service ou fonction =
J54: Véhicule personnel (NDF à établir) =
A55: Je certifie l'exactitude de toutes les données renseignées.
A56: Fait le : | C56: =TODAY() -> 45320 | J56: Nom / Prénom de la hiérarchie :
B57: Signature du Collaborateur : | J57: Signature de la Hiérarchie après contrôles :
A63: Fiche à conserver durant 3 ans | J63: Fiche à retourner à votre Gestionnaire du Personnel

Sheet Niveau 1 Juillet
D2: ASTREINTE niveau 1 | L2: 45474
B5: RETOUR DU PRESENT DOCUMENT AU GESTIONNAIRE DU PERSONNEL AVANT LE | L5: 45475
B6: = Zones de saisie informatique svp
B7: = Zones de saisie manuscrite svp
A8: Nom : | H8: Région / Exploit. :
A10: Prénom : | H10: Statut / Emploi :
A13: Date | D13: Périodes d'Astreinte niveau 1 | F13: Type d'astreinte A B C ou D | H13: Heure de début d'astreinte le 1er jour | K13: Heure de fin d'astreinte le dernier jour | M13: Commentaires / remarques
A14: 45439
A15: 45440
A16: 45441
A17: 45442
A18: 45443
A19: 45444
A20: 45445
A21: 45446
A22: 45447
A23: 45448
A24: 45449
A25: 45450
... A48: 45473
A49: TOTAL DE LA PERIODE | D49: =+COUNTA(D14:E48) -> 0 | F49: =+COUNTA(F14:G48) -> 0
D50: jours de niveau 1
A52: Je certifie l'exactitude de toutes les données renseignées.
A53: Fait le : | C53: =TODAY() -> 45320 | J53: Nom / Prénom de la hiérarchie :
B54: Signature du Collaborateur : | J54: Signature de la Hiérarchie après contrôles :
A60: Fiche à conserver durant 3 ans | J60: Fiche à retourner à votre Gestionnaire du Personnel

Sheet Niveau 2 Juillet
D2: ASTREINTE niveau 2 | L2: ='Niveau 1 Juillet'!L2:N4 -> 45474
B5: RETOUR DU PRESENT DOCUMENT AU GESTIONNAIRE DU PERSONNEL AVANT LE | L5: =+'Niveau 1 Juillet'!L5:N5 -> 45475
B6: = Zones de saisie informatique svp
B7: = Zones de saisie manuscrite svp
A8: Nom : | H8: Région / Exploit. :
A10: Prénom : | H10: Statut / Emploi :
A12: Type d'astreinte | H12: Heure de début : | M12: le 1er jour
H13: Heure de fin : | M13: le dernier jour
F15: INTERVENTION PHYSIQUE
A16: Date | D16: Périodes d'Astreinte niveau 2 | F16: Où et pour quel motif ? | H16: Temps trajet domicile | J16: Heure début intervention | K16: Heure fin d'intervention | M16: Quelle durée d'intervention ?
A17: 45439 | M17: =+K17-J17 -> 0
A18: 45440 | M18: =+K18-J18 -> 0
A19: 45441 | M19: =+K19-J19 -> 0
A20: 45442 | M20: =+K20-J20 -> 0
A21: 45443 | M21: =+K21-J21 -> 0
A22: 45444 | M22: =+K22-J22 -> 0
A23: 45445 | M23: =+K23-J23 -> 0
A24: 45446 | M24: =+K24-J24 -> 0
A25: 45447 | M25: =+K25-J25 -> 0
A26: 45448 | M26: =+K26-J26 -> 0
A27: 45449 | M27: =+K27-J27 -> 0
A28: 45450 | M28: =+K28-J28 -> 0
... A44: 45466 | M44: =+K44-J44 -> 0
A45: 45467
A46: 45468
A47: 45469
A48: 45470
A49: 45471
A50: 45472
A51: 45473
A52: TOTAL DE LA PERIODE | D52: =+COUNTA(D17:E51) -> 0 | F52: =+COUNTA(F17:G51) -> 0 | H52: =SUM(H17:I51) -> 0 | M52: =+SUM(M17:O51) -> 0
D53: jours | F53: interventions | H53: heures | M53: h d'interventions
A55: En cas d'intervention sur le terrain, quel moyen de transport avez-vous utilisé ? | J55: Véhicule de service ou fonction =
J56: Véhicule personnel (NDF à établir) =
A57: Je certifie l'exactitude de toutes les données renseignées.
A58: Fait le : | C58: =TODAY() -> 45320 | J58: Nom / Prénom de la hiérarchie :
J59: Signature de la Hiérarchie après contrôles :
A65: Fiche à conserver durant 3 ans | J65: Fiche à retourner à votre Gestionnaire du Personnel

Sheet Mixte Juillet
D2: ASTREINTE MIXTE | L2: ='Niveau 1 Juillet'!L2:N4 -> 45474
B5: RETOUR DU PRESENT DOCUMENT AU GESTIONNAIRE DU PERSONNEL AVANT LE | L5: =+'Niveau 1 Juillet'!L5:N5 -> 45475
B6: = Zones de saisie informatique svp
B7: = Zones de saisie manuscrite svp
A8: Nom : | H8: Région / Exploit. :
A10: Prénom : | H10: Statut / Emploi :
A12: Type d'astreinte | C12: A ou B ou C ou D | H12: Heure de début : | M12: le 1er jour
H13: Heure de fin : | M13: le dernier jour
A14: Type de rémunération : niveau 1
F15: INTERVENTION PHYSIQUE
A16: Date | D16: Périodes d'Astreinte niveau 2 | F16: Où et pour quel motif ? | H16: Temps trajet domicile | J16: Heure début intervention | K16: Heure fin d'intervention | M16: Quelle durée d'intervention ?
A17: 45439 | M17: =+K17-J17 -> 0
A18: 45440 | M18: =+K18-J18 -> 0
A19: 45441 | M19: =+K19-J19 -> 0
A20: 45442 | M20: =+K20-J20 -> 0
A21: 45443 | M21: =+K21-J21 -> 0
A22: 45444 | M22: =+K22-J22 -> 0
A23: 45445 | M23: =+K23-J23 -> 0
A24: 45446 | M24: =+K24-J24 -> 0
A25: 45447 | M25: =+K25-J25 -> 0
A26: 45448 | M26: =+K26-J26 -> 0
A27: 45449 | M27: =+K27-J27 -> 0
A28: 45450 | M28: =+K28-J28 -> 0
... A44: 45466 | M44: =+K44-J44 -> 0
A45: 45467
A46: 45468
A47: 45469
A48: 45470
A49: 45471
A50: 45472
A51: 45473
A52: TOTAL DE LA PERIODE | D52: =+COUNTA(D17:E51) -> 0 | F52: =+COUNTA(F17:G51) -> 0 | H52: =SUM(H17:I51) -> 0 | M52: =+SUM(M17:O51) -> 0
D53: jours | F53: interventions | H53: heures | M53: h d'interventions
A55: En cas d'intervention sur le terrain, quel moyen de transport avez-vous utilisé ? | J55: Véhicule de service ou fonction =
J56: Véhicule personnel (NDF à établir) =
A57: Je certifie l'exactitude de toutes les données renseignées.
A58: Fait le : | C58: =TODAY() -> 45320 | J58: Nom / Prénom de la hiérarchie :
B59: Signature du Collaborateur : | J59: Signature de la Hiérarchie après contrôles :
A65: Fiche à conserver durant 3 ans | J65: Fiche à retourner à votre Gestionnaire du Personnel

Sheet Niveau 1 Août
D2: ASTREINTE niveau 1 | L2: 45505
B5: RETOUR DU PRESENT DOCUMENT AU GESTIONNAIRE DU PERSONNEL AVANT LE | L5: 45503
B6: = Zones de saisie informatique svp
B7: = Zones de saisie manuscrite svp
A8: Nom : | H8: Région / Exploit. :
A10: Prénom : | H10: Statut / Emploi :
A13: Date | D13: Périodes d'Astreinte niveau 1 | F13: Type d'astreinte A B C ou D | H13: Heure de début d'astreinte le 1er jour | K13: Heure de fin d'astreinte le dernier jour | M13: Commentaires / remarques
A14: 45474
A15: 45475
A16: 45476
A17: 45477
A18: 45478
A19: 45479
A20: 45480
A21: 45481
A22: 45482
A23: 45483
A24: 45484
A25: 45485
... A41: 45501
A42: TOTAL DE LA PERIODE | D42: =+COUNTA(D14:E41) -> 0 | F42: =+COUNTA(F14:G41) -> 0
D43: jours de niveau 1
A45: Je certifie l'exactitude de toutes les données renseignées.
A46: Fait le : | C46: =TODAY() -> 45320 | J46: Nom / Prénom de la hiérarchie :
B47: Signature du Collaborateur : | J47: Signature de la Hiérarchie après contrôles :
A53: Fiche à conserver durant 3 ans | J53: Fiche à retourner à votre Gestionnaire du Personnel

Sheet Niveau 2 Août
D2: ASTREINTE niveau 2 | L2: ='Niveau 1 Août'!L2:N4 -> 45505
B5: RETOUR DU PRESENT DOCUMENT AU GESTIONNAIRE DU PERSONNEL AVANT LE | L5: =+'Niveau 1 Août'!L5:N5 -> 45503
B6: = Zones de saisie informatique svp
B7: = Zones de saisie manuscrite svp
A8: Nom : | H8: Région / Exploit. :
A10: Prénom : | H10: Statut / Emploi :
A12: Type d'astreinte | H12: Heure de début : | M12: le 1er jour
H13: Heure de fin : | M13: le dernier jour
F15: INTERVENTION PHYSIQUE
A16: Date | D16: Périodes d'Astreinte niveau 2 | F16: Où et pour quel motif ? | H16: Temps trajet domicile | J16: Heure début intervention | K16: Heure fin d'intervention | M16: Quelle durée d'intervention ?
A17: 45474 | M17: =+K17-J17 -> 0
A18: 45475 | M18: =+K18-J18 -> 0
A19: 45476 | M19: =+K19-J19 -> 0
A20: 45477 | M20: =+K20-J20 -> 0
A21: 45478 | M21: =+K21-J21 -> 0
A22: 45479 | M22: =+K22-J22 -> 0
A23: 45480 | M23: =+K23-J23 -> 0
A24: 45481 | M24: =+K24-J24 -> 0
A25: 45482 | M25: =+K25-J25 -> 0
A26: 45483 | M26: =+K26-J26 -> 0
A27: 45484 | M27: =+K27-J27 -> 0
A28: 45485 | M28: =+K28-J28 -> 0
... A44: 45501 | M44: =+K44-J44 -> 0
A45: TOTAL DE LA PERIODE | D45: =+COUNTA(D17:E44) -> 0 | F45: =+COUNTA(F17:G44) -> 0 | H45: =SUM(H17:I44) -> 0 | M45: =+SUM(M17:O44) -> 0
D46: jours | F46: interventions | H46: heures | M46: h d'interventions
A48: En cas d'intervention sur le terrain, quel moyen de transport avez-vous utilisé ? | J48: Véhicule de service ou fonction =
J49: Véhicule personnel (NDF à établir) =
A50: Je certifie l'exactitude de toutes les données renseignées.
A51: Fait le : | C51: =TODAY() -> 45320 | J51: Nom / Prénom de la hiérarchie :
B52: Signature du Collaborateur : | J52: Signature de la Hiérarchie après contrôles :
A58: Fiche à conserver durant 3 ans | J58: Fiche à retourner à votre Gestionnaire du Personnel

Sheet Mixte Août
D2: ASTREINTE MIXTE | L2: ='Niveau 1 Août'!L2:N4 -> 45505
B5: RETOUR DU PRESENT DOCUMENT AU GESTIONNAIRE DU PERSONNEL AVANT LE | L5: =+'Niveau 2 Août'!L5:N5 -> 45503
B6: = Zones de saisie informatique svp
B7: = Zones de saisie manuscrite svp
A8: Nom : | H8: Région / Exploit. :
A10: Prénom : | H10: Statut / Emploi :
A12: Type d'astreinte | C12: A ou B ou C ou D | H12: Heure de début : | M12: le 1er jour
H13: Heure de fin : | M13: le dernier jour
A14: Type de rémunération : niveau 1
F15: INTERVENTION PHYSIQUE
A16: Date | D16: Périodes d'Astreinte niveau 2 | F16: Où et pour quel motif ? | H16: Temps trajet domicile | J16: Heure début intervention | K16: Heure fin d'intervention | M16: Quelle durée d'intervention ?
A17: 45474 | M17: =+K17-J17 -> 0
A18: 45475 | M18: =+K18-J18 -> 0
A19: 45476 | M19: =+K19-J19 -> 0
A20: 45477 | M20: =+K20-J20 -> 0
A21: 45478 | M21: =+K21-J21 -> 0
A22: 45479 | M22: =+K22-J22 -> 0
A23: 45480 | M23: =+K23-J23 -> 0
A24: 45481 | M24: =+K24-J24 -> 0
A25: 45482 | M25: =+K25-J25 -> 0
A26: 45483 | M26: =+K26-J26 -> 0
A27: 45484 | M27: =+K27-J27 -> 0
A28: 45485 | M28: =+K28-J28 -> 0
... A44: 45501 | M44: =+K44-J44 -> 0
A45: TOTAL DE LA PERIODE | D45: =+COUNTA(D17:E44) -> 0 | F45: =+COUNTA(F17:G44) -> 0 | H45: =SUM(H17:I44) -> 0 | M45: =+SUM(M17:O44) -> 0
D46: jours | F46: interventions | H46: heures | M46: h d'interventions
A48: En cas d'intervention sur le terrain, quel moyen de transport avez-vous utilisé ? | J48: Véhicule de service ou fonction =
J49: Véhicule personnel (NDF à établir) =
A50: Je certifie l'exactitude de toutes les données renseignées.
A51: Fait le : | C51: =TODAY() -> 45320 | J51: Nom / Prénom de la hiérarchie :
B52: Signature du Collaborateur : | J52: Signature de la Hiérarchie après contrôles :
A58: Fiche à conserver durant 3 ans | J58: Fiche à retourner à votre Gestionnaire du Personnel

Sheet Niveau 1 Sept
D2: ASTREINTE niveau 1 | L2: 45536
B5: RETOUR DU PRESENT DOCUMENT AU GESTIONNAIRE DU PERSONNEL AVANT LE | L5: 45531
B6: = Zones de saisie informatique svp
B7: = Zones de saisie manuscrite svp
A8: Nom : | H8: Région / Exploit. :
A10: Prénom : | H10: Statut / Emploi :
A13: Date | D13: Périodes d'Astreinte niveau 1 | F13: Type d'astreinte A B C ou D | H13: Heure de début d'astreinte le 1er jour | K13: Heure de fin d'astreinte le dernier jour | M13: Commentaires / remarques
A14: 45502
A15: 45503
A16: 45504
A17: 45505
A18: 45506
A19: 45507
A20: 45508
A21: 45509
A22: 45510
A23: 45511
A24: 45512
A25: 45513
... A41: 45529
A42: TOTAL DE LA PERIODE | D42: =+COUNTA(D14:E41) -> 0 | F42: =+COUNTA(F14:F41) -> 0
D43: jours de niveau 1
A47: Je certifie l'exactitude de toutes les données renseignées.
A48: Fait le : | C48: =TODAY() -> 45320 | J48: Nom / Prénom de la hiérarchie :
B49: Signature du Collaborateur : | J49: Signature de la Hiérarchie après contrôles :
A55: Fiche à conserver durant 3 ans | J55: Fiche à retourner à votre Gestionnaire du Personnel

Sheet Niveau 2 Sept
D2: ASTREINTE niveau 2 | L2: ='Niveau 1 Sept'!L2:N4 -> 45536
B5: RETOUR DU PRESENT DOCUMENT AU GESTIONNAIRE DU PERSONNEL AVANT LE | L5: =+'Niveau 1 Sept'!L5:N5 -> 45531
B6: = Zones de saisie informatique svp
B7: = Zones de saisie manuscrite svp
A8: Nom : | H8: Région / Exploit. :
A10: Prénom : | H10: Statut / Emploi :
A12: Type d'astreinte | H12: Heure de début : | M12: le 1er jour
H13: Heure de fin : | M13: le dernier jour
F15: INTERVENTION PHYSIQUE
A16: Date | D16: Périodes d'Astreinte niveau 2 | F16: Où et pour quel motif ? | H16: Temps trajet domicile | J16: Heure début intervention | K16: Heure fin d'intervention | M16: Quelle durée d'intervention ?
A17: 45502 | M17: =+K17-J17 -> 0
A18: 45503 | M18: =+K18-J18 -> 0
A19: 45504 | M19: =+K19-J19 -> 0
A20: 45505 | M20: =+K20-J20 -> 0
A21: 45506 | M21: =+K21-J21 -> 0
A22: 45507 | M22: =+K22-J22 -> 0
A23: 45508 | M23: =+K23-J23 -> 0
A24: 45509 | M24: =+K24-J24 -> 0
A25: 45510 | M25: =+K25-J25 -> 0
A26: 45511 | M26: =+K26-J26 -> 0
A27: 45512 | M27: =+K27-J27 -> 0
A28: 45513 | M28: =+K28-J28 -> 0
... A44: 45529 | M44: =+K44-J44 -> 0
A45: TOTAL DE LA PERIODE | D45: =+COUNTA(D17:E44) -> 0 | F45: =+COUNTA(F17:G44) -> 0 | H45: =SUM(H17:I44) -> 0 | M45: =+SUM(M17:O44) -> 0
D46: jours | F46: interventions | H46: heures | M46: h d'interventions
A48: En cas d'intervention sur le terrain, quel moyen de transport avez-vous utilisé ? | J48: Véhicule de service ou fonction =
J49: Véhicule personnel (NDF à établir) =
A50: Je certifie l'exactitude de toutes les données renseignées.
A51: Fait le : | C51: =TODAY() -> 45320 | J51: Nom / Prénom de la hiérarchie :
B52: Signature du Collaborateur : | J52: Signature de la Hiérarchie après contrôles :
A58: Fiche à conserver durant 3 ans | J58: Fiche à retourner à votre Gestionnaire du Personnel

Sheet Mixte Sept
D2: ASTREINTE MIXTE | L2: ='Niveau 1 Sept'!L2:N4 -> 45536
B5: RETOUR DU PRESENT DOCUMENT AU GESTIONNAIRE DU PERSONNEL AVANT LE | L5: =+'Niveau 2 Sept'!L5:N5 -> 45531
B6: = Zones de saisie informatique svp
B7: = Zones de saisie manuscrite svp
A8: Nom : | H8: Région / Exploit. :
A10: Prénom : | H10: Statut / Emploi :
A12: Type d'astreinte | C12: A ou B ou C ou D | H12: Heure de début : | M12: le 1er jour
H13: Heure de fin : | M13: le dernier jour
A14: Type de rémunération : niveau 1
F15: INTERVENTION PHYSIQUE
A16: Date | D16: Périodes d'Astreinte niveau 2 | F16: Où et pour quel motif ? | H16: Temps trajet domicile | J16: Heure début intervention | K16: Heure fin d'intervention | M16: Quelle durée d'intervention ?
A17: 45502 | M17: =+K17-J17 -> 0
A18: 45503 | M18: =+K18-J18 -> 0
A19: 45504 | M19: =+K19-J19 -> 0
A20: 45505 | M20: =+K20-J20 -> 0
A21: 45506 | M21: =+K21-J21 -> 0
A22: 45507 | M22: =+K22-J22 -> 0
A23: 45508 | M23: =+K23-J23 -> 0
A24: 45509 | M24: =+K24-J24 -> 0
A25: 45510 | M25: =+K25-J25 -> 0
A26: 45511 | M26: =+K26-J26 -> 0
A27: 45512 | M27: =+K27-J27 -> 0
A28: 45513 | M28: =+K28-J28 -> 0
... A44: 45529 | M44: =+K44-J44 -> 0
A45: TOTAL DE LA PERIODE | D45: =+COUNTA(D17:E44) -> 0 | F45: =+COUNTA(F17:G44) -> 0 | H45: =SUM(H17:I44) -> 0 | M45: =+SUM(M17:O44) -> 0
D46: jours | F46: interventions | H46: heures | M46: h d'interventions
A48: En cas d'intervention sur le terrain, quel moyen de transport avez-vous utilisé ? | J48: Véhicule de service ou fonction =
J49: Véhicule personnel (NDF à établir) =
A50: Je certifie l'exactitude de toutes les données renseignées.
A51: Fait le : | C51: =TODAY() -> 45320 | J51: Nom / Prénom de la hiérarchie :
B52: Signature du Collaborateur : | J52: Signature de la Hiérarchie après contrôles :
A58: Fiche à conserver durant 3 ans | J58: Fiche à retourner à votre Gestionnaire du Personnel

Sheet Niveau 1 Oct
D2: ASTREINTE niveau 1 | L2: 45566
B5: RETOUR DU PRESENT DOCUMENT AU GESTIONNAIRE DU PERSONNEL AVANT LE | L5: 45566
B6: = Zones de saisie informatique svp
B7: = Zones de saisie manuscrite svp
A8: Nom : | H8: Région / Exploit. :
A10: Prénom : | H10: Statut / Emploi :
A12: Date | D12: Périodes d'Astreinte niveau 1 | F12: Type d'astreinte A B C ou D | H12: Heure de début d'astreinte le 1er jour | K12: Heure de fin d'astreinte le dernier jour | M12: Commentaires / remarques
A13: 45530
A14: 45531
A15: 45532
A16: 45533
A17: 45534
A18: 45535
A19: 45536
A20: 45537
A21: 45538
A22: 45539
A23: 45540
A24: 45541
... A47: 45564
A48: TOTAL DE LA PERIODE | D48: =+COUNTA(D13:E47) -> 0 | F48: =+COUNTA(F13:G47) -> 0
D49: jours de niveau 1
A51: Je certifie l'exactitude de toutes les données renseignées.
A52: Fait le : | C52: =TODAY() -> 45320 | J52: Nom / Prénom de la hiérarchie :
B53: Signature du Collaborateur : | J53: Signature de la Hiérarchie après contrôles :
A59: Fiche à conserver durant 3 ans | J59: Fiche à retourner à votre Gestionnaire du Personnel

Sheet Niveau 2 Oct
D2: ASTREINTE niveau 2 | L2: ='Niveau 1 Oct'!L2:N4 -> 45566
B5: RETOUR DU PRESENT DOCUMENT AU GESTIONNAIRE DU PERSONNEL AVANT LE | L5: =+'Niveau 1 Oct'!L5:N5 -> 45566
B6: = Zones de saisie informatique svp
B7: = Zones de saisie manuscrite svp
A8: Nom : | H8: Région / Exploit. :
A10: Prénom : | H10: Statut / Emploi :
A12: Type d'astreinte | H12: Heure de début : | M12: le 1er jour
H13: Heure de fin : | M13: le dernier jour
F15: INTERVENTION PHYSIQUE
A16: Date | D16: Périodes d'Astreinte niveau 2 | F16: Où et pour quel motif ? | H16: Temps trajet domicile | J16: Heure début intervention | K16: Heure fin d'intervention | M16: Quelle durée d'intervention ?
A17: 45530 | M17: =+K17-J17 -> 0
A18: 45531 | M18: =+K18-J18 -> 0
A19: 45532 | M19: =+K19-J19 -> 0
A20: 45533 | M20: =+K20-J20 -> 0
A21: 45534 | M21: =+K21-J21 -> 0
A22: 45535 | M22: =+K22-J22 -> 0
A23: 45536 | M23: =+K23-J23 -> 0
A24: 45537 | M24: =+K24-J24 -> 0
A25: 45538 | M25: =+K25-J25 -> 0
A26: 45539 | M26: =+K26-J26 -> 0
A27: 45540 | M27: =+K27-J27 -> 0
A28: 45541 | M28: =+K28-J28 -> 0
... A44: 45557 | M44: =+K44-J44 -> 0
A45: 45558
A46: 45559
A47: 45560
A48: 45561
A49: 45562
A50: 45563
A51: 45564
A52: TOTAL DE LA PERIODE | D52: =+COUNTA(D17:E51) -> 0 | F52: =+COUNTA(F17:G51) -> 0 | H52: =SUM(H17:I51) -> 0 | M52: =+SUM(M17:O51) -> 0
D53: jours | F53: interventions | H53: heures | M53: h d'interventions
A55: En cas d'intervention sur le terrain, quel moyen de transport avez-vous utilisé ? | J55: Véhicule de service ou fonction =
J56: Véhicule personnel (NDF à établir) =
A57: Je certifie l'exactitude de toutes les données renseignées.
A58: Fait le : | C58: =TODAY() -> 45320 | J58: Nom / Prénom de la hiérarchie :
B59: Signature du Collaborateur : | J59: Signature de la Hiérarchie après contrôles :
A65: Fiche à conserver durant 3 ans | J65: Fiche à retourner à votre Gestionnaire du Personnel

Sheet Mixte Oct
D2: ASTREINTE MIXTE | L2: ='Niveau 1 Oct'!L2:N4 -> 45566
B5: RETOUR DU PRESENT DOCUMENT AU GESTIONNAIRE DU PERSONNEL AVANT LE | L5: =+'Niveau 1 Oct'!L5:N5 -> 45566
B6: = Zones de saisie informatique svp
B7: = Zones de saisie manuscrite svp
A8: Nom : | H8: Région / Exploit. :
A10: Prénom : | H10: Statut / Emploi :
A12: Type d'astreinte | C12: A ou B ou C ou D | H12: Heure de début : | M12: le 1er jour
H13: Heure de fin : | M13: le dernier jour
A14: Type de rémunération : niveau 1
F15: INTERVENTION PHYSIQUE
A16: Date | D16: Périodes d'Astreinte niveau 2 | F16: Où et pour quel motif ? | H16: Temps trajet domicile | J16: Heure début intervention | K16: Heure fin d'intervention | M16: Quelle durée d'intervention ?
A17: 45530 | M17: =+K17-J17 -> 0
A18: 45531 | M18: =+K18-J18 -> 0
A19: 45532 | M19: =+K19-J19 -> 0
A20: 45533 | M20: =+K20-J20 -> 0
A21: 45534 | M21: =+K21-J21 -> 0
A22: 45535 | M22: =+K22-J22 -> 0
A23: 45536 | M23: =+K23-J23 -> 0
A24: 45537 | M24: =+K24-J24 -> 0
A25: 45538 | M25: =+K25-J25 -> 0
A26: 45539 | M26: =+K26-J26 -> 0
A27: 45540 | M27: =+K27-J27 -> 0
A28: 45541 | M28: =+K28-J28 -> 0
... A44: 45557 | M44: =+K44-J44 -> 0
A45: 45558
A46: 45559
A47: 45560
A48: 45561
A49: 45562
A50: 45563
A51: 45564
A52: TOTAL DE LA PERIODE | D52: =+COUNTA(D17:E51) -> 0 | F52: =+COUNTA(F17:G51) -> 0 | H52: =SUM(H17:I51) -> 0 | M52: =+SUM(M17:O51) -> 0
D53: jours | F53: interventions | H53: heures | M53: h d'interventions
A55: En cas d'intervention sur le terrain, quel moyen de transport avez-vous utilisé ? | J55: Véhicule de service ou fonction =
J56: Véhicule personnel (NDF à établir) =
A57: Je certifie l'exactitude de toutes les données renseignées.
A58: Fait le : | C58: =TODAY() -> 45320 | J58: Nom / Prénom de la hiérarchie :
B59: Signature du Collaborateur : | J59: Signature de la Hiérarchie après contrôles :
A65: Fiche à conserver durant 3 ans | J65: Fiche à retourner à votre Gestionnaire du Personnel

Sheet Niveau 1 Nov
D2: ASTREINTE niveau 1 | L2: 45597
B5: RETOUR DU PRESENT DOCUMENT AU GESTIONNAIRE DU PERSONNEL AVANT LE | L5: 45594
B6: = Zones de saisie informatique svp
B7: = Zones de saisie manuscrite svp
A8: Nom : | H8: Région / Exploit. :
A10: Prénom : | H10: Statut / Emploi :
A13: Date | D13: Périodes d'Astreinte niveau 1 | F13: Type d'astreinte A B C ou D | H13: Heure de début d'astreinte le 1er jour | K13: Heure de fin d'astreinte le dernier jour | M13: Commentaires / remarques
A14: 45565
A15: 45566
A16: 45567
A17: 45568
A18: 45569
A19: 45570
A20: 45571
A21: 45572
A22: 45573
A23: 45574
A24: 45575
A25: 45576
... A41: 45592
A42: TOTAL DE LA PERIODE | D42: =+COUNTA(D14:E41) -> 0 | F42: =+COUNTA(F14:G41) -> 0
D43: jours de niveau 1
A45: Je certifie l'exactitude de toutes les données renseignées.
A46: Fait le : | C46: =TODAY() -> 45320 | J46: Nom / Prénom de la hiérarchie :
B47: Signature du Collaborateur : | J47: Signature de la Hiérarchie après contrôles :
A53: Fiche à conserver durant 3 ans | J53: Fiche à retourner à votre Gestionnaire du Personnel

Sheet Niveau 2 Nov
D2: ASTREINTE niveau 2 | L2: ='Niveau 1 Nov'!L2:N4 -> 45597
B5: RETOUR DU PRESENT DOCUMENT AU GESTIONNAIRE DU PERSONNEL AVANT LE | L5: =+'Niveau 1 Nov'!L5:N5 -> 45594
B6: = Zones de saisie informatique svp
B7: = Zones de saisie manuscrite svp
A8: Nom : | H8: Région / Exploit. :
A10: Prénom : | H10: Statut / Emploi :
A12: Type d'astreinte | H12: Heure de début : | M12: le 1er jour
H13: Heure de fin : | M13: le dernier jour
F15: INTERVENTION PHYSIQUE
A16: Date | D16: Périodes d'Astreinte niveau 2 | F16: Où et pour quel motif ? | H16: Temps trajet domicile | J16: Heure début intervention | K16: Heure fin d'intervention | M16: Quelle durée d'intervention ?
A17: 45565 | M17: =+K17-J17 -> 0
A18: 45566 | M18: =+K18-J18 -> 0
A19: 45567 | M19: =+K19-J19 -> 0
A20: 45568 | M20: =+K20-J20 -> 0
A21: 45569 | M21: =+K21-J21 -> 0
A22: 45570 | M22: =+K22-J22 -> 0
A23: 45571 | M23: =+K23-J23 -> 0
A24: 45572 | M24: =+K24-J24 -> 0
A25: 45573 | M25: =+K25-J25 -> 0
A26: 45574 | M26: =+K26-J26 -> 0
A27: 45575 | M27: =+K27-J27 -> 0
A28: 45576 | M28: =+K28-J28 -> 0
... A44: 45592 | M44: =+K44-J44 -> 0
A45: TOTAL DE LA PERIODE | D45: =+COUNTA(D17:E44) -> 0 | F45: =+COUNTA(F17:G44) -> 0 | H45: =SUM(H17:I44) -> 0 | M45: =+SUM(M17:O44) -> 0
D46: jours | F46: interventions | H46: heures | M46: h d'interventions
A48: En cas d'intervention sur le terrain, quel moyen de transport avez-vous utilisé ? | J48: Véhicule de service ou fonction =
J49: Véhicule personnel (NDF à établir) =
A50: Je certifie l'exactitude de toutes les données renseignées.
A51: Fait le : | C51: =TODAY() -> 45320 | J51: Nom / Prénom de la hiérarchie :
B52: Signature du Collaborateur : | J52: Signature de la Hiérarchie après contrôles :
A58: Fiche à conserver durant 3 ans | J58: Fiche à retourner à votre Gestionnaire du Personnel

Sheet Mixte Nov
D2: ASTREINTE MIXTE | L2: ='Niveau 1 Nov'!L2:N4 -> 45597
B5: RETOUR DU PRESENT DOCUMENT AU GESTIONNAIRE DU PERSONNEL AVANT LE | L5: =+'Niveau 1 Nov'!L5:N5 -> 45594
B6: = Zones de saisie informatique svp
B7: = Zones de saisie manuscrite svp
A8: Nom : | H8: Région / Exploit. :
A10: Prénom : | H10: Statut / Emploi :
A12: Type d'astreinte | C12: A ou B ou C ou D | H12: Heure de début : | M12: le 1er jour
H13: Heure de fin : | M13: le dernier jour
A14: Type de rémunération : niveau 1
F15: INTERVENTION PHYSIQUE
A16: Date | D16: Périodes d'Astreinte niveau 2 | F16: Où et pour quel motif ? | H16: Temps trajet domicile | J16: Heure début intervention | K16: Heure fin d'intervention | M16: Quelle durée d'intervention ?
A17: 45565 | M17: =+K17-J17 -> 0
A18: 45566 | M18: =+K18-J18 -> 0
A19: 45567 | M19: =+K19-J19 -> 0
A20: 45568 | M20: =+K20-J20 -> 0
A21: 45569 | M21: =+K21-J21 -> 0
A22: 45570 | M22: =+K22-J22 -> 0
A23: 45571 | M23: =+K23-J23 -> 0
A24: 45572 | M24: =+K24-J24 -> 0
A25: 45573 | M25: =+K25-J25 -> 0
A26: 45574 | M26: =+K26-J26 -> 0
A27: 45575 | M27: =+K27-J27 -> 0
A28: 45576 | M28: =+K28-J28 -> 0
... A44: 45592 | M44: =+K44-J44 -> 0
A45: TOTAL DE LA PERIODE | D45: =+COUNTA(D17:E44) -> 0 | F45: =+COUNTA(F17:G44) -> 0 | H45: =SUM(H17:I44) -> 0 | M45: =+SUM(M17:O44) -> 0
D46: jours | F46: interventions | H46: heures | M46: h d'interventions
A48: En cas d'intervention sur le terrain, quel moyen de transport avez-vous utilisé ? | J48: Véhicule de service ou fonction =
J49: Véhicule personnel (NDF à établir) =
A50: Je certifie l'exactitude de toutes les données renseignées.
A51: Fait le : | C51: =TODAY() -> 45320 | J51: Nom / Prénom de la hiérarchie :
B52: Signature du Collaborateur : | J52: Signature de la Hiérarchie après contrôles :
A58: Fiche à conserver durant 3 ans | J58: Fiche à retourner à votre Gestionnaire du Personnel

Sheet Niveau 1 Déc
D2: ASTREINTE niveau 1 | L2: 45627
B5: RETOUR DU PRESENT DOCUMENT AU GESTIONNAIRE DU PERSONNEL AVANT LE | L5: 45622
B6: = Zones de saisie informatique svp
B7: = Zones de saisie manuscrite svp
A8: Nom : | H8: Région / Exploit. :
A10: Prénom : | H10: Statut / Emploi :
A13: Date | D13: Périodes d'Astreinte niveau 1 | F13: Type d'astreinte A B C ou D | H13: Heure de début d'astreinte le 1er jour | K13: Heure de fin d'astreinte le dernier jour | M13: Commentaires / remarques
A14: 45593
A15: 45594
A16: 45595
A17: 45596
A18: 45597
A19: 45598
A20: 45599
A21: 45600
A22: 45601
A23: 45602
A24: 45603
A25: 45604
... A41: 45620
A42: TOTAL DE LA PERIODE | D42: =+COUNTA(D14:E41) -> 0 | F42: =+COUNTA(F14:G41) -> 0
D43: jours de niveau 1
A45: Je certifie l'exactitude de toutes les données renseignées.
A46: Fait le : | C46: =TODAY() -> 45320 | J46: Nom / Prénom de la hiérarchie :
B47: Signature du Collaborateur : | J47: Signature de la Hiérarchie après contrôles :
A53: Fiche à conserver durant 3 ans | J53: Fiche à retourner à votre Gestionnaire du Personnel

Sheet Niveau 2 Déc
D2: ASTREINTE niveau 2 | L2: ='Niveau 1 Déc'!L2:N4 -> 45627
B5: RETOUR DU PRESENT DOCUMENT AU GESTIONNAIRE DU PERSONNEL AVANT LE | L5: =+'Niveau 1 Déc'!L5:N5 -> 45622
B6: = Zones de saisie informatique svp
B7: = Zones de saisie manuscrite svp
A8: Nom : | H8: Région / Exploit. :
A10: Prénom : | H10: Statut / Emploi :
A12: Type d'astreinte | H12: Heure de début : | M12: le 1er jour
H13: Heure de fin : | M13: le dernier jour
F15: INTERVENTION PHYSIQUE
A16: Date | D16: Périodes d'Astreinte niveau 2 | F16: Où et pour quel motif ? | H16: Temps trajet domicile | J16: Heure début intervention | K16: Heure fin d'intervention | M16: Quelle durée d'intervention ?
A17: 45593 | M17: =+K17-J17 -> 0
A18: 45594 | M18: =+K18-J18 -> 0
A19: 45595 | M19: =+K19-J19 -> 0
A20: 45596 | M20: =+K20-J20 -> 0
A21: 45597 | M21: =+K21-J21 -> 0
A22: 45598 | M22: =+K22-J22 -> 0
A23: 45599 | M23: =+K23-J23 -> 0
A24: 45600 | M24: =+K24-J24 -> 0
A25: 45601 | M25: =+K25-J25 -> 0
A26: 45602 | M26: =+K26-J26 -> 0
A27: 45603 | M27: =+K27-J27 -> 0
A28: 45604 | M28: =+K28-J28 -> 0
... A44: 45620 | M44: =+K44-J44 -> 0
A45: TOTAL DE LA PERIODE | D45: =+COUNTA(D17:E44) -> 0 | F45: =+COUNTA(F17:G44) -> 0 | H45: =SUM(H17:I44) -> 0 | M45: =+SUM(M17:O44) -> 0
D46: jours | F46: interventions | H46: heures | M46: h d'interventions
A48: En cas d'intervention sur le terrain, quel moyen de transport avez-vous utilisé ? | J48: Véhicule de service ou fonction =
J49: Véhicule personnel (NDF à établir) =
A50: Je certifie l'exactitude de toutes les données renseignées.
A51: Fait le : | C51: =TODAY() -> 45320 | J51: Nom / Prénom de la hiérarchie :
B52: Signature du Collaborateur : | J52: Signature de la Hiérarchie après contrôles :
A58: Fiche à conserver durant 3 ans | J58: Fiche à retourner à votre Gestionnaire du Personnel

Sheet Mixte Déc
D2: ASTREINTE MIXTE | L2: ='Niveau 1 Déc'!L2:N4 -> 45627
B5: RETOUR DU PRESENT DOCUMENT AU GESTIONNAIRE DU PERSONNEL AVANT LE | L5: =+'Niveau 1 Déc'!L5:N5 -> 45622
B6: = Zones de saisie informatique svp
B7: = Zones de saisie manuscrite svp
A8: Nom : | H8: Région / Exploit. :
A10: Prénom : | H10: Statut / Emploi :
A12: Type d'astreinte | C12: A ou B ou C ou D | H12: Heure de début : | M12: le 1er jour
H13: Heure de fin : | M13: le dernier jour
A14: Type de rémunération : niveau 1
F15: INTERVENTION PHYSIQUE
A16: Date | D16: Périodes d'Astreinte niveau 2 | F16: Où et pour quel motif ? | H16: Temps trajet domicile | J16: Heure début intervention | K16: Heure fin d'intervention | M16: Quelle durée d'intervention ?
A17: 45593 | M17: =+K17-J17 -> 0
